<?xml version="1.0" encoding="utf-8"?>
<!-- This URDF was automatically created by SolidWorks to URDF Exporter! Originally created by Stephen Brawner (brawner@gmail.com) 
     Commit Version: 1.6.0-4-g7f85cfe  Build Version: 1.6.7995.38578
     For more information, please see http://wiki.ros.org/sw_urdf_exporter -->
<robot
  name="main6">
  <link
    name="base_link">
    <inertial>
      <origin
        xyz="0.0044986 3.256E-05 0.28819"
        rpy="0 0 0" />
      <mass
        value="9.25" />
      <inertia
        ixx="0.015059"
        ixy="4.8108E-07"
        ixz="4.8621E-06"
        iyy="0.021353"
        iyz="-6.425E-08"
        izz="0.032191" />
    </inertial>
    <visual>
      <origin
        xyz="0 0 0"
        rpy="0 0 0" />
      <geometry>
        <mesh
          filename="../meshes/base_link.STL" />
      </geometry>
      <material
        name="">
        <color
          rgba="0.79216 0.81961 0.93333 1" />
      </material>
    </visual>
    <collision>
      <origin
        xyz="0 0 0"
        rpy="0 0 0" />
      <geometry>
        <mesh
          filename="../meshes/base_link.STL" />
      </geometry>
    </collision>
  </link>
  <link
    name="lf0_Link">
    <inertial>
      <origin
        xyz="-0.063173 -0.016938 0.036295"
        rpy="0 0 0" />
      <mass
        value="0.31" />
      <inertia
        ixx="7.4747E-05"
        ixy="-4.9593E-06"
        ixz="8.6857E-05"
        iyy="0.00024801"
        iyz="2.8492E-06"
        izz="0.00017603" />
    </inertial>
    <visual>
      <origin
        xyz="0 0 0"
        rpy="0 0 0" />
      <geometry>
        <mesh
          filename="../meshes/lf0_Link.STL" />
      </geometry>
      <material
        name="">
        <color
          rgba="0.79216 0.81961 0.93333 1" />
      </material>
    </visual>
    <collision>
      <origin
        xyz="0 0 0"
        rpy="0 0 0" />
      <geometry>
        <mesh
          filename="../meshes/lf0_Link.STL" />
      </geometry>
    </collision>
  </link>
  <joint
    name="lf0_Joint"
    type="continuous">
    <origin
      xyz="-0.091 0.187 0.315"
      rpy="3.1416 0.29923 0" />
    <parent
      link="base_link" />
    <child
      link="lf0_Link" />
    <axis
      xyz="0 1 0" />
    <limit
      lower="0"
      upper="0"
      effort="0"
      velocity="0" />
  </joint>
  <link
    name="lf1_Link">
    <inertial>
      <origin
        xyz="0.101 -0.019609 0.093571"
        rpy="0 0 0" />
      <mass
        value="0.38" />
      <inertia
        ixx="0.00069059"
        ixy="9.4441E-06"
        ixz="-0.00069228"
        iyy="0.0014842"
        iyz="8.7494E-06"
        izz="0.00079648" />
    </inertial>
    <visual>
      <origin
        xyz="0 0 0"
        rpy="0 0 0" />
      <geometry>
        <mesh
          filename="../meshes/lf1_Link.STL" />
      </geometry>
      <material
        name="">
        <color
          rgba="0.79216 0.81961 0.93333 1" />
      </material>
    </visual>
    <collision>
      <origin
        xyz="0 0 0"
        rpy="0 0 0" />
      <geometry>
        <mesh
          filename="../meshes/lf1_Link.STL" />
      </geometry>
    </collision>
  </link>
  <joint
    name="lf1_Joint"
    type="continuous">
    <origin
      xyz="-0.13006 -0.016351 0.074724"
      rpy="0 0.15695 0" />
    <parent
      link="lf0_Link" />
    <child
      link="lf1_Link" />
    <axis
      xyz="0 1 0" />
    <limit
      lower="0"
      upper="0"
      effort="0"
      velocity="0" />
  </joint>
  <link
    name="l_wheel_Link">
    <inertial>
      <origin
        xyz="0 -0.01385 -6.9389E-18"
        rpy="0 0 0" />
      <mass
        value="1.71" />
      <inertia
        ixx="0.00033555"
        ixy="-3.3964E-20"
        ixz="-3.1764E-22"
        iyy="0.00051182"
        iyz="3.3976E-20"
        izz="0.00033555" />
    </inertial>
    <visual>
      <origin
        xyz="0 0 0"
        rpy="0 0 0" />
      <geometry>
        <mesh
          filename="../meshes/l_wheel_Link.STL" />
      </geometry>
      <material
        name="">
        <color
          rgba="0.79216 0.81961 0.93333 1" />
      </material>
    </visual>
    <collision>
      <origin
        xyz="0 0 0"
        rpy="0 0 0" />
      <geometry>
        <mesh
          filename="../meshes/l_wheel_Link.STL" />
      </geometry>
    </collision>
  </link>
  <joint
    name="l_wheel_Joint"
    type="continuous">
    <origin
      xyz="0.22007 0 0.20388"
      rpy="3.1416 0.14082 0" />
    <parent
      link="lf1_Link" />
    <child
      link="l_wheel_Link" />
    <axis
      xyz="0 -1 0" />
  </joint>
  <link
    name="rf0_Link">
    <inertial>
      <origin
        xyz="-0.063173 -0.016938 0.036295"
        rpy="0 0 0" />
      <mass
        value="0.31" />
      <inertia
        ixx="7.4747E-05"
        ixy="-4.9593E-06"
        ixz="8.6857E-05"
        iyy="0.00024801"
        iyz="2.8492E-06"
        izz="0.00017603" />
    </inertial>
    <visual>
      <origin
        xyz="0 0 0"
        rpy="0 0 0" />
      <geometry>
        <mesh
          filename="../meshes/rf0_Link.STL" />
      </geometry>
      <material
        name="">
        <color
          rgba="0.79216 0.81961 0.93333 1" />
      </material>
    </visual>
    <collision>
      <origin
        xyz="0 0 0"
        rpy="0 0 0" />
      <geometry>
        <mesh
          filename="../meshes/rf0_Link.STL" />
      </geometry>
    </collision>
  </link>
  <joint
    name="rf0_Joint"
    type="continuous">
    <origin
      xyz="-0.091 -0.187 0.315"
      rpy="0 -0.74372 0" />
    <parent
      link="base_link" />
    <child
      link="rf0_Link" />
    <axis
      xyz="0 1 0" />
    <limit
      lower="0"
      upper="0"
      effort="0"
      velocity="0" />
  </joint>
  <link
    name="rf1_Link">
    <inertial>
      <origin
        xyz="0.101 -0.019609 0.093571"
        rpy="0 0 0" />
      <mass
        value="0.38" />
      <inertia
        ixx="0.00069059"
        ixy="9.4441E-06"
        ixz="-0.00069228"
        iyy="0.0014842"
        iyz="8.7494E-06"
        izz="0.00079648" />
    </inertial>
    <visual>
      <origin
        xyz="0 0 0"
        rpy="0 0 0" />
      <geometry>
        <mesh
          filename="../meshes/rf1_Link.STL" />
      </geometry>
      <material
        name="">
        <color
          rgba="0.79216 0.81961 0.93333 1" />
      </material>
    </visual>
    <collision>
      <origin
        xyz="0 0 0"
        rpy="0 0 0" />
      <geometry>
        <mesh
          filename="../meshes/rf1_Link.STL" />
      </geometry>
    </collision>
  </link>
  <joint
    name="rf1_Joint"
    type="continuous">
    <origin
      xyz="-0.13006 -0.016351 0.074724"
      rpy="3.1416 0.76112 3.1416" />
    <parent
      link="rf0_Link" />
    <child
      link="rf1_Link" />
    <axis
      xyz="0 1 0" />
    <limit
      lower="0"
      upper="0"
      effort="0"
      velocity="0" />
  </joint>
  <link
    name="r_wheel_Link">
    <inertial>
      <origin
        xyz="9.7145E-16 0.01385 4.3021E-16"
        rpy="0 0 0" />
      <mass
        value="1.71" />
      <inertia
        ixx="0.00033555"
        ixy="-3.4103E-20"
        ixz="-4.2352E-22"
        iyy="0.00051182"
        iyz="3.3957E-20"
        izz="0.00033555" />
    </inertial>
    <visual>
      <origin
        xyz="0 0 0"
        rpy="0 0 0" />
      <geometry>
        <mesh
          filename="../meshes/r_wheel_Link.STL" />
      </geometry>
      <material
        name="">
        <color
          rgba="0.79216 0.81961 0.93333 1" />
      </material>
    </visual>
    <collision>
      <origin
        xyz="0 0 0"
        rpy="0 0 0" />
      <geometry>
        <mesh
          filename="../meshes/r_wheel_Link.STL" />
      </geometry>
    </collision>
  </link>
  <joint
    name="r_wheel_Joint"
    type="continuous">
    <origin
      xyz="0.22007 0 0.20388"
      rpy="3.1416 -1.5063 3.1416" />
    <parent
      link="rf1_Link" />
    <child
      link="r_wheel_Link" />
    <axis
      xyz="0 -1 0" />
  </joint>
</robot>